<?xml version="1.0"?>
<robot xmlns:xacro="http://www.ros.org/wiki/xacro" name="diff_drive_robot">

  <!-- XACRO property for pi -->
  <xacro:property name="pi" value="3.14159265359"/>

  <xacro:include filename="inertial_macros.xacro"/>
  <xacro:include filename="materials.xacro"/>
  <xacro:include filename="gazebo.xacro"/>

  <!-- Ground Reference -->
    <link name="base_footprint"/>
    
    <joint name="base_footprint_joint" type="fixed">
        <parent link="base_footprint"/>
        <child link="base_link"/>
        <origin xyz="-0.1 0 0" rpy="0 0 0"/>
    </joint>
    
  <!-- Base link -->
  <!-- <link name="base_link">
  </link> -->

  <!-- Chassis link -->
  <!-- <joint name="chassis_joint" type="fixed">
    <parent link="base_link"/>
    <child link="chassis"/>
    <origin xyz="-0.1 0 0"/>
  </joint> -->

  <link name="base_link">
    <visual>
      <origin xyz="0.15 0 0.075"/>
      <geometry>
        <box size="0.3 0.3 0.15"/>
      </geometry>
      <material name="white"/>
    </visual>
    <collision>
        <origin xyz="0.15 0 0.075"/>
        <geometry>
            <box size="0.3 0.3 0.15"/>
        </geometry>
    </collision>
    <xacro:inertial_box mass="0.5" x="0.3" y="0.3" z="0.15">
        <origin xyz="0.15 0 0.075" rpy="0 0 0"/>
    </xacro:inertial_box>
  </link>

  <!-- Left wheel -->
  <joint name="left_wheel_joint" type="continuous">
        <parent link="base_link"/>
        <child link="left_wheel"/>
        <!-- Y = chassis_width/2 + wheel_thickness/2 = 0.15 + 0.02 = 0.17 -->
        <origin xyz="0.1 0.17 0" rpy="-${pi/2} 0 0"/>
        <axis xyz="0 0 1"/>
    </joint>

    <link name="left_wheel">
        <visual>
            <geometry>
                <cylinder radius="0.05" length="0.04"/>
            </geometry>
            <material name="blue"/>
        </visual>
        <collision>
            <geometry>
                <cylinder radius="0.05" length="0.04"/>
            </geometry>
        </collision>
        <xacro:inertial_cylinder mass="0.1" length="0.04" radius="0.05">
            <origin xyz="0 0 0" rpy="0 0 0"/>
        </xacro:inertial_cylinder>
    </link>

    <!-- Right wheel -->
    <joint name="right_wheel_joint" type="continuous">
        <parent link="base_link"/>
        <child link="right_wheel"/>
        <!-- Y = -(chassis_width/2 + wheel_thickness/2) = -0.17 -->
        <origin xyz="0.1 -0.17 0" rpy="-${pi/2} 0 0"/>
        <axis xyz="0 0 1"/>
    </joint>

    <link name="right_wheel">
        <visual>
            <geometry>
                <cylinder radius="0.05" length="0.04"/>
            </geometry>
            <material name="blue"/>
        </visual>
        <collision>
            <geometry>
                <cylinder radius="0.05" length="0.04"/>
            </geometry>
        </collision>
        <xacro:inertial_cylinder mass="0.1" length="0.04" radius="0.05">
            <origin xyz="0 0 0" rpy="0 0 0"/>
        </xacro:inertial_cylinder>
    </link>


  <!-- Caster wheel -->
  <joint name="caster_wheel_joint" type="fixed">
    <parent link="base_link"/>
    <child link="caster_wheel"/>
    <origin xyz="0.24 0 0"/>
  </joint>

  <link name="caster_wheel">
    <visual>
      <geometry>
        <sphere radius="0.05"/>
      </geometry>
      <material name="black"/>
    </visual>
    <collision>
        <geometry>
            <sphere radius="0.05"/>
        </geometry>
    </collision>
    <xacro:inertial_sphere mass="0.1" radius="0.05">
        <origin xyz="0 0 0" rpy="0 0 0"/>
    </xacro:inertial_sphere>
  </link>

  <!-- IMU -->
  <link name="imu_frame"/>

    <joint name="imu_joint" type="fixed">
        <parent link="base_link"/>
        <child link="imu_frame"/>
        <origin xyz="0.0 0.0 0.08" rpy="0.0 0.0 0.0"/>
    </joint>

  

</robot>
